[2025-04-29T07:57:34.458+0000] {local_task_job_runner.py:123} INFO - ::group::Pre task execution logs
[2025-04-29T07:57:34.465+0000] {taskinstance.py:2614} INFO - Dependencies all met for dep_context=non-requeueable deps ti=<TaskInstance: all_classification_pipeline.preprocess_images manual__2025-04-29T07:57:28.727521+00:00 [queued]>
[2025-04-29T07:57:34.468+0000] {taskinstance.py:2614} INFO - Dependencies all met for dep_context=requeueable deps ti=<TaskInstance: all_classification_pipeline.preprocess_images manual__2025-04-29T07:57:28.727521+00:00 [queued]>
[2025-04-29T07:57:34.468+0000] {taskinstance.py:2867} INFO - Starting attempt 1 of 2
[2025-04-29T07:57:34.474+0000] {taskinstance.py:2890} INFO - Executing <Task(PythonOperator): preprocess_images> on 2025-04-29 07:57:28.727521+00:00
[2025-04-29T07:57:34.478+0000] {standard_task_runner.py:72} INFO - Started process 66 to run task
[2025-04-29T07:57:34.481+0000] {standard_task_runner.py:104} INFO - Running: ['airflow', 'tasks', 'run', 'all_classification_pipeline', 'preprocess_images', 'manual__2025-04-29T07:57:28.727521+00:00', '--job-id', '35', '--raw', '--subdir', 'DAGS_FOLDER/classification_pipeline.py', '--cfg-path', '/tmp/tmp3opmwhlf']
[2025-04-29T07:57:34.482+0000] {standard_task_runner.py:105} INFO - Job 35: Subtask preprocess_images
[2025-04-29T07:57:34.505+0000] {task_command.py:467} INFO - Running <TaskInstance: all_classification_pipeline.preprocess_images manual__2025-04-29T07:57:28.727521+00:00 [running]> on host 7ae1210dc4f8
[2025-04-29T07:57:34.537+0000] {taskinstance.py:3134} INFO - Exporting env vars: AIRFLOW_CTX_DAG_OWNER='airflow' AIRFLOW_CTX_DAG_ID='all_classification_pipeline' AIRFLOW_CTX_TASK_ID='preprocess_images' AIRFLOW_CTX_EXECUTION_DATE='2025-04-29T07:57:28.727521+00:00' AIRFLOW_CTX_TRY_NUMBER='1' AIRFLOW_CTX_DAG_RUN_ID='manual__2025-04-29T07:57:28.727521+00:00'
[2025-04-29T07:57:34.538+0000] {taskinstance.py:732} INFO - ::endgroup::
[2025-04-29T07:57:35.799+0000] {taskinstance.py:3313} ERROR - Task failed with exception
Traceback (most recent call last):
  File "/home/airflow/.local/lib/python3.9/site-packages/airflow/models/taskinstance.py", line 768, in _execute_task
    result = _execute_callable(context=context, **execute_callable_kwargs)
  File "/home/airflow/.local/lib/python3.9/site-packages/airflow/models/taskinstance.py", line 734, in _execute_callable
    return ExecutionCallableRunner(
  File "/home/airflow/.local/lib/python3.9/site-packages/airflow/utils/operator_helpers.py", line 252, in run
    return self.func(*args, **kwargs)
  File "/home/airflow/.local/lib/python3.9/site-packages/airflow/models/baseoperator.py", line 424, in wrapper
    return func(self, *args, **kwargs)
  File "/home/airflow/.local/lib/python3.9/site-packages/airflow/operators/python.py", line 238, in execute
    return_value = self.execute_callable()
  File "/home/airflow/.local/lib/python3.9/site-packages/airflow/operators/python.py", line 256, in execute_callable
    return runner.run(*self.op_args, **self.op_kwargs)
  File "/home/airflow/.local/lib/python3.9/site-packages/airflow/utils/operator_helpers.py", line 252, in run
    return self.func(*args, **kwargs)
  File "/opt/scripts/preprocess.py", line 15, in resize_images
    out_cls.mkdir(parents=True, exist_ok=True)
  File "/usr/local/lib/python3.9/pathlib.py", line 1323, in mkdir
    self._accessor.mkdir(self, mode)
FileExistsError: [Errno 17] File exists: '/opt/data/processed/.DS_Store'
[2025-04-29T07:57:35.804+0000] {taskinstance.py:1226} INFO - Marking task as UP_FOR_RETRY. dag_id=all_classification_pipeline, task_id=preprocess_images, run_id=manual__2025-04-29T07:57:28.727521+00:00, execution_date=20250429T075728, start_date=20250429T075734, end_date=20250429T075735
[2025-04-29T07:57:35.814+0000] {taskinstance.py:341} INFO - ::group::Post task execution logs
[2025-04-29T07:57:35.815+0000] {standard_task_runner.py:124} ERROR - Failed to execute job 35 for task preprocess_images ([Errno 17] File exists: '/opt/data/processed/.DS_Store'; 66)
Traceback (most recent call last):
  File "/home/airflow/.local/lib/python3.9/site-packages/airflow/task/task_runner/standard_task_runner.py", line 117, in _start_by_fork
    ret = args.func(args, dag=self.dag)
  File "/home/airflow/.local/lib/python3.9/site-packages/airflow/cli/cli_config.py", line 49, in command
    return func(*args, **kwargs)
  File "/home/airflow/.local/lib/python3.9/site-packages/airflow/utils/cli.py", line 116, in wrapper
    return f(*args, **kwargs)
  File "/home/airflow/.local/lib/python3.9/site-packages/airflow/cli/commands/task_command.py", line 483, in task_run
    task_return_code = _run_task_by_selected_method(args, _dag, ti)
  File "/home/airflow/.local/lib/python3.9/site-packages/airflow/cli/commands/task_command.py", line 256, in _run_task_by_selected_method
    return _run_raw_task(args, ti)
  File "/home/airflow/.local/lib/python3.9/site-packages/airflow/cli/commands/task_command.py", line 341, in _run_raw_task
    return ti._run_raw_task(
  File "/home/airflow/.local/lib/python3.9/site-packages/airflow/utils/session.py", line 97, in wrapper
    return func(*args, session=session, **kwargs)
  File "/home/airflow/.local/lib/python3.9/site-packages/airflow/models/taskinstance.py", line 3006, in _run_raw_task
    return _run_raw_task(
  File "/home/airflow/.local/lib/python3.9/site-packages/airflow/models/taskinstance.py", line 274, in _run_raw_task
    TaskInstance._execute_task_with_callbacks(
  File "/home/airflow/.local/lib/python3.9/site-packages/airflow/models/taskinstance.py", line 3161, in _execute_task_with_callbacks
    result = self._execute_task(context, task_orig)
  File "/home/airflow/.local/lib/python3.9/site-packages/airflow/models/taskinstance.py", line 3185, in _execute_task
    return _execute_task(self, context, task_orig)
  File "/home/airflow/.local/lib/python3.9/site-packages/airflow/models/taskinstance.py", line 768, in _execute_task
    result = _execute_callable(context=context, **execute_callable_kwargs)
  File "/home/airflow/.local/lib/python3.9/site-packages/airflow/models/taskinstance.py", line 734, in _execute_callable
    return ExecutionCallableRunner(
  File "/home/airflow/.local/lib/python3.9/site-packages/airflow/utils/operator_helpers.py", line 252, in run
    return self.func(*args, **kwargs)
  File "/home/airflow/.local/lib/python3.9/site-packages/airflow/models/baseoperator.py", line 424, in wrapper
    return func(self, *args, **kwargs)
  File "/home/airflow/.local/lib/python3.9/site-packages/airflow/operators/python.py", line 238, in execute
    return_value = self.execute_callable()
  File "/home/airflow/.local/lib/python3.9/site-packages/airflow/operators/python.py", line 256, in execute_callable
    return runner.run(*self.op_args, **self.op_kwargs)
  File "/home/airflow/.local/lib/python3.9/site-packages/airflow/utils/operator_helpers.py", line 252, in run
    return self.func(*args, **kwargs)
  File "/opt/scripts/preprocess.py", line 15, in resize_images
    out_cls.mkdir(parents=True, exist_ok=True)
  File "/usr/local/lib/python3.9/pathlib.py", line 1323, in mkdir
    self._accessor.mkdir(self, mode)
FileExistsError: [Errno 17] File exists: '/opt/data/processed/.DS_Store'
[2025-04-29T07:57:35.821+0000] {local_task_job_runner.py:266} INFO - Task exited with return code 1
[2025-04-29T07:57:35.832+0000] {taskinstance.py:3901} INFO - 0 downstream tasks scheduled from follow-on schedule check
[2025-04-29T07:57:35.832+0000] {local_task_job_runner.py:245} INFO - ::endgroup::
