[2025-04-30T05:25:06.460+0000] {local_task_job_runner.py:123} INFO - ::group::Pre task execution logs
[2025-04-30T05:25:06.504+0000] {taskinstance.py:2614} INFO - Dependencies all met for dep_context=non-requeueable deps ti=<TaskInstance: all_classification_pipeline.train_classifier scheduled__2025-04-29T00:00:00+00:00 [queued]>
[2025-04-30T05:25:06.528+0000] {taskinstance.py:2614} INFO - Dependencies all met for dep_context=requeueable deps ti=<TaskInstance: all_classification_pipeline.train_classifier scheduled__2025-04-29T00:00:00+00:00 [queued]>
[2025-04-30T05:25:06.529+0000] {taskinstance.py:2867} INFO - Starting attempt 1 of 2
[2025-04-30T05:25:06.585+0000] {taskinstance.py:2890} INFO - Executing <Task(PythonOperator): train_classifier> on 2025-04-29 00:00:00+00:00
[2025-04-30T05:25:06.623+0000] {standard_task_runner.py:72} INFO - Started process 108 to run task
[2025-04-30T05:25:06.629+0000] {standard_task_runner.py:104} INFO - Running: ['airflow', 'tasks', 'run', 'all_classification_pipeline', 'train_classifier', 'scheduled__2025-04-29T00:00:00+00:00', '--job-id', '89', '--raw', '--subdir', 'DAGS_FOLDER/classification_pipeline.py', '--cfg-path', '/tmp/tmpklz4rh2n']
[2025-04-30T05:25:06.635+0000] {standard_task_runner.py:105} INFO - Job 89: Subtask train_classifier
[2025-04-30T05:25:06.966+0000] {task_command.py:467} INFO - Running <TaskInstance: all_classification_pipeline.train_classifier scheduled__2025-04-29T00:00:00+00:00 [running]> on host 65641cff057b
[2025-04-30T05:25:07.303+0000] {taskinstance.py:3134} INFO - Exporting env vars: AIRFLOW_CTX_DAG_OWNER='airflow' AIRFLOW_CTX_DAG_ID='all_classification_pipeline' AIRFLOW_CTX_TASK_ID='train_classifier' AIRFLOW_CTX_EXECUTION_DATE='2025-04-29T00:00:00+00:00' AIRFLOW_CTX_TRY_NUMBER='1' AIRFLOW_CTX_DAG_RUN_ID='scheduled__2025-04-29T00:00:00+00:00'
[2025-04-30T05:25:07.306+0000] {taskinstance.py:732} INFO - ::endgroup::
[2025-04-30T05:25:07.461+0000] {connectionpool.py:827} WARNING - Retrying (JitteredRetry(total=6, connect=6, read=7, redirect=7, status=7)) after connection broken by 'NewConnectionError('<urllib3.connection.HTTPConnection object at 0x7f356c78a850>: Failed to establish a new connection: [Errno 111] Connection refused')': /api/2.0/mlflow/experiments/get-by-name?experiment_name=ALL_Classifier
[2025-04-30T05:25:11.473+0000] {connectionpool.py:827} WARNING - Retrying (JitteredRetry(total=5, connect=5, read=7, redirect=7, status=7)) after connection broken by 'NewConnectionError('<urllib3.connection.HTTPConnection object at 0x7f356c78aeb0>: Failed to establish a new connection: [Errno 111] Connection refused')': /api/2.0/mlflow/experiments/get-by-name?experiment_name=ALL_Classifier
[2025-04-30T05:25:19.476+0000] {connectionpool.py:827} WARNING - Retrying (JitteredRetry(total=4, connect=4, read=7, redirect=7, status=7)) after connection broken by 'NewConnectionError('<urllib3.connection.HTTPConnection object at 0x7f356c721820>: Failed to establish a new connection: [Errno 111] Connection refused')': /api/2.0/mlflow/experiments/get-by-name?experiment_name=ALL_Classifier
[2025-04-30T05:25:35.497+0000] {connectionpool.py:827} WARNING - Retrying (JitteredRetry(total=3, connect=3, read=7, redirect=7, status=7)) after connection broken by 'NewConnectionError('<urllib3.connection.HTTPConnection object at 0x7f356c7211f0>: Failed to establish a new connection: [Errno 111] Connection refused')': /api/2.0/mlflow/experiments/get-by-name?experiment_name=ALL_Classifier
[2025-04-30T05:26:07.506+0000] {connectionpool.py:827} WARNING - Retrying (JitteredRetry(total=2, connect=2, read=7, redirect=7, status=7)) after connection broken by 'NewConnectionError('<urllib3.connection.HTTPConnection object at 0x7f356c7210a0>: Failed to establish a new connection: [Errno 111] Connection refused')': /api/2.0/mlflow/experiments/get-by-name?experiment_name=ALL_Classifier
[2025-04-30T05:27:11.564+0000] {connectionpool.py:827} WARNING - Retrying (JitteredRetry(total=1, connect=1, read=7, redirect=7, status=7)) after connection broken by 'NewConnectionError('<urllib3.connection.HTTPConnection object at 0x7f356c7217c0>: Failed to establish a new connection: [Errno 111] Connection refused')': /api/2.0/mlflow/experiments/get-by-name?experiment_name=ALL_Classifier
[2025-04-30T05:29:11.599+0000] {connectionpool.py:827} WARNING - Retrying (JitteredRetry(total=0, connect=0, read=7, redirect=7, status=7)) after connection broken by 'NewConnectionError('<urllib3.connection.HTTPConnection object at 0x7f356c7217f0>: Failed to establish a new connection: [Errno 111] Connection refused')': /api/2.0/mlflow/experiments/get-by-name?experiment_name=ALL_Classifier
[2025-04-30T05:29:11.708+0000] {taskinstance.py:3313} ERROR - Task failed with exception
Traceback (most recent call last):
  File "/home/airflow/.local/lib/python3.9/site-packages/urllib3/connection.py", line 174, in _new_conn
    conn = connection.create_connection(
  File "/home/airflow/.local/lib/python3.9/site-packages/urllib3/util/connection.py", line 95, in create_connection
    raise err
  File "/home/airflow/.local/lib/python3.9/site-packages/urllib3/util/connection.py", line 85, in create_connection
    sock.connect(sa)
ConnectionRefusedError: [Errno 111] Connection refused

During handling of the above exception, another exception occurred:

Traceback (most recent call last):
  File "/home/airflow/.local/lib/python3.9/site-packages/urllib3/connectionpool.py", line 716, in urlopen
    httplib_response = self._make_request(
  File "/home/airflow/.local/lib/python3.9/site-packages/urllib3/connectionpool.py", line 416, in _make_request
    conn.request(method, url, **httplib_request_kw)
  File "/home/airflow/.local/lib/python3.9/site-packages/urllib3/connection.py", line 244, in request
    super(HTTPConnection, self).request(method, url, body=body, headers=headers)
  File "/usr/local/lib/python3.9/http/client.py", line 1285, in request
    self._send_request(method, url, body, headers, encode_chunked)
  File "/usr/local/lib/python3.9/http/client.py", line 1331, in _send_request
    self.endheaders(body, encode_chunked=encode_chunked)
  File "/usr/local/lib/python3.9/http/client.py", line 1280, in endheaders
    self._send_output(message_body, encode_chunked=encode_chunked)
  File "/usr/local/lib/python3.9/http/client.py", line 1040, in _send_output
    self.send(msg)
  File "/usr/local/lib/python3.9/http/client.py", line 980, in send
    self.connect()
  File "/home/airflow/.local/lib/python3.9/site-packages/urllib3/connection.py", line 205, in connect
    conn = self._new_conn()
  File "/home/airflow/.local/lib/python3.9/site-packages/urllib3/connection.py", line 186, in _new_conn
    raise NewConnectionError(
urllib3.exceptions.NewConnectionError: <urllib3.connection.HTTPConnection object at 0x7f356c721be0>: Failed to establish a new connection: [Errno 111] Connection refused

During handling of the above exception, another exception occurred:

Traceback (most recent call last):
  File "/home/airflow/.local/lib/python3.9/site-packages/requests/adapters.py", line 667, in send
    resp = conn.urlopen(
  File "/home/airflow/.local/lib/python3.9/site-packages/urllib3/connectionpool.py", line 830, in urlopen
    return self.urlopen(
  File "/home/airflow/.local/lib/python3.9/site-packages/urllib3/connectionpool.py", line 830, in urlopen
    return self.urlopen(
  File "/home/airflow/.local/lib/python3.9/site-packages/urllib3/connectionpool.py", line 830, in urlopen
    return self.urlopen(
  [Previous line repeated 4 more times]
  File "/home/airflow/.local/lib/python3.9/site-packages/urllib3/connectionpool.py", line 802, in urlopen
    retries = retries.increment(
  File "/home/airflow/.local/lib/python3.9/site-packages/urllib3/util/retry.py", line 594, in increment
    raise MaxRetryError(_pool, url, error or ResponseError(cause))
urllib3.exceptions.MaxRetryError: HTTPConnectionPool(host='mlflow', port=5000): Max retries exceeded with url: /api/2.0/mlflow/experiments/get-by-name?experiment_name=ALL_Classifier (Caused by NewConnectionError('<urllib3.connection.HTTPConnection object at 0x7f356c721be0>: Failed to establish a new connection: [Errno 111] Connection refused'))

During handling of the above exception, another exception occurred:

Traceback (most recent call last):
  File "/home/airflow/.local/lib/python3.9/site-packages/mlflow/utils/rest_utils.py", line 184, in http_request
    return _get_http_response_with_retries(
  File "/home/airflow/.local/lib/python3.9/site-packages/mlflow/utils/request_utils.py", line 237, in _get_http_response_with_retries
    return session.request(method, url, allow_redirects=allow_redirects, **kwargs)
  File "/home/airflow/.local/lib/python3.9/site-packages/requests/sessions.py", line 589, in request
    resp = self.send(prep, **send_kwargs)
  File "/home/airflow/.local/lib/python3.9/site-packages/requests/sessions.py", line 703, in send
    r = adapter.send(request, **kwargs)
  File "/home/airflow/.local/lib/python3.9/site-packages/requests/adapters.py", line 700, in send
    raise ConnectionError(e, request=request)
requests.exceptions.ConnectionError: HTTPConnectionPool(host='mlflow', port=5000): Max retries exceeded with url: /api/2.0/mlflow/experiments/get-by-name?experiment_name=ALL_Classifier (Caused by NewConnectionError('<urllib3.connection.HTTPConnection object at 0x7f356c721be0>: Failed to establish a new connection: [Errno 111] Connection refused'))

During handling of the above exception, another exception occurred:

Traceback (most recent call last):
  File "/home/airflow/.local/lib/python3.9/site-packages/airflow/models/taskinstance.py", line 768, in _execute_task
    result = _execute_callable(context=context, **execute_callable_kwargs)
  File "/home/airflow/.local/lib/python3.9/site-packages/airflow/models/taskinstance.py", line 734, in _execute_callable
    return ExecutionCallableRunner(
  File "/home/airflow/.local/lib/python3.9/site-packages/airflow/utils/operator_helpers.py", line 252, in run
    return self.func(*args, **kwargs)
  File "/home/airflow/.local/lib/python3.9/site-packages/airflow/models/baseoperator.py", line 424, in wrapper
    return func(self, *args, **kwargs)
  File "/home/airflow/.local/lib/python3.9/site-packages/airflow/operators/python.py", line 238, in execute
    return_value = self.execute_callable()
  File "/home/airflow/.local/lib/python3.9/site-packages/airflow/operators/python.py", line 256, in execute_callable
    return runner.run(*self.op_args, **self.op_kwargs)
  File "/home/airflow/.local/lib/python3.9/site-packages/airflow/utils/operator_helpers.py", line 252, in run
    return self.func(*args, **kwargs)
  File "/opt/scripts/train_classifier.py", line 58, in train_classifier
    mlflow.set_experiment("ALL_Classifier")
  File "/home/airflow/.local/lib/python3.9/site-packages/mlflow/tracking/fluent.py", line 157, in set_experiment
    experiment = client.get_experiment_by_name(experiment_name)
  File "/home/airflow/.local/lib/python3.9/site-packages/mlflow/tracking/client.py", line 1703, in get_experiment_by_name
    return self._tracking_client.get_experiment_by_name(name)
  File "/home/airflow/.local/lib/python3.9/site-packages/mlflow/tracking/_tracking_service/client.py", line 591, in get_experiment_by_name
    return self.store.get_experiment_by_name(name)
  File "/home/airflow/.local/lib/python3.9/site-packages/mlflow/store/tracking/rest_store.py", line 641, in get_experiment_by_name
    response_proto = self._call_endpoint(GetExperimentByName, req_body)
  File "/home/airflow/.local/lib/python3.9/site-packages/mlflow/store/tracking/rest_store.py", line 90, in _call_endpoint
    return call_endpoint(self.get_host_creds(), endpoint, method, json_body, response_proto)
  File "/home/airflow/.local/lib/python3.9/site-packages/mlflow/utils/rest_utils.py", line 397, in call_endpoint
    response = http_request(**call_kwargs)
  File "/home/airflow/.local/lib/python3.9/site-packages/mlflow/utils/rest_utils.py", line 207, in http_request
    raise MlflowException(f"API request to {url} failed with exception {e}")
mlflow.exceptions.MlflowException: API request to http://mlflow:5000/api/2.0/mlflow/experiments/get-by-name failed with exception HTTPConnectionPool(host='mlflow', port=5000): Max retries exceeded with url: /api/2.0/mlflow/experiments/get-by-name?experiment_name=ALL_Classifier (Caused by NewConnectionError('<urllib3.connection.HTTPConnection object at 0x7f356c721be0>: Failed to establish a new connection: [Errno 111] Connection refused'))
[2025-04-30T05:29:12.118+0000] {taskinstance.py:1226} INFO - Marking task as UP_FOR_RETRY. dag_id=all_classification_pipeline, task_id=train_classifier, run_id=scheduled__2025-04-29T00:00:00+00:00, execution_date=20250429T000000, start_date=20250430T052506, end_date=20250430T052912
[2025-04-30T05:29:12.329+0000] {taskinstance.py:341} INFO - ::group::Post task execution logs
[2025-04-30T05:29:12.342+0000] {standard_task_runner.py:124} ERROR - Failed to execute job 89 for task train_classifier (API request to http://mlflow:5000/api/2.0/mlflow/experiments/get-by-name failed with exception HTTPConnectionPool(host='mlflow', port=5000): Max retries exceeded with url: /api/2.0/mlflow/experiments/get-by-name?experiment_name=ALL_Classifier (Caused by NewConnectionError('<urllib3.connection.HTTPConnection object at 0x7f356c721be0>: Failed to establish a new connection: [Errno 111] Connection refused')); 108)
Traceback (most recent call last):
  File "/home/airflow/.local/lib/python3.9/site-packages/urllib3/connection.py", line 174, in _new_conn
    conn = connection.create_connection(
  File "/home/airflow/.local/lib/python3.9/site-packages/urllib3/util/connection.py", line 95, in create_connection
    raise err
  File "/home/airflow/.local/lib/python3.9/site-packages/urllib3/util/connection.py", line 85, in create_connection
    sock.connect(sa)
ConnectionRefusedError: [Errno 111] Connection refused

During handling of the above exception, another exception occurred:

Traceback (most recent call last):
  File "/home/airflow/.local/lib/python3.9/site-packages/urllib3/connectionpool.py", line 716, in urlopen
    httplib_response = self._make_request(
  File "/home/airflow/.local/lib/python3.9/site-packages/urllib3/connectionpool.py", line 416, in _make_request
    conn.request(method, url, **httplib_request_kw)
  File "/home/airflow/.local/lib/python3.9/site-packages/urllib3/connection.py", line 244, in request
    super(HTTPConnection, self).request(method, url, body=body, headers=headers)
  File "/usr/local/lib/python3.9/http/client.py", line 1285, in request
    self._send_request(method, url, body, headers, encode_chunked)
  File "/usr/local/lib/python3.9/http/client.py", line 1331, in _send_request
    self.endheaders(body, encode_chunked=encode_chunked)
  File "/usr/local/lib/python3.9/http/client.py", line 1280, in endheaders
    self._send_output(message_body, encode_chunked=encode_chunked)
  File "/usr/local/lib/python3.9/http/client.py", line 1040, in _send_output
    self.send(msg)
  File "/usr/local/lib/python3.9/http/client.py", line 980, in send
    self.connect()
  File "/home/airflow/.local/lib/python3.9/site-packages/urllib3/connection.py", line 205, in connect
    conn = self._new_conn()
  File "/home/airflow/.local/lib/python3.9/site-packages/urllib3/connection.py", line 186, in _new_conn
    raise NewConnectionError(
urllib3.exceptions.NewConnectionError: <urllib3.connection.HTTPConnection object at 0x7f356c721be0>: Failed to establish a new connection: [Errno 111] Connection refused

During handling of the above exception, another exception occurred:

Traceback (most recent call last):
  File "/home/airflow/.local/lib/python3.9/site-packages/requests/adapters.py", line 667, in send
    resp = conn.urlopen(
  File "/home/airflow/.local/lib/python3.9/site-packages/urllib3/connectionpool.py", line 830, in urlopen
    return self.urlopen(
  File "/home/airflow/.local/lib/python3.9/site-packages/urllib3/connectionpool.py", line 830, in urlopen
    return self.urlopen(
  File "/home/airflow/.local/lib/python3.9/site-packages/urllib3/connectionpool.py", line 830, in urlopen
    return self.urlopen(
  [Previous line repeated 4 more times]
  File "/home/airflow/.local/lib/python3.9/site-packages/urllib3/connectionpool.py", line 802, in urlopen
    retries = retries.increment(
  File "/home/airflow/.local/lib/python3.9/site-packages/urllib3/util/retry.py", line 594, in increment
    raise MaxRetryError(_pool, url, error or ResponseError(cause))
urllib3.exceptions.MaxRetryError: HTTPConnectionPool(host='mlflow', port=5000): Max retries exceeded with url: /api/2.0/mlflow/experiments/get-by-name?experiment_name=ALL_Classifier (Caused by NewConnectionError('<urllib3.connection.HTTPConnection object at 0x7f356c721be0>: Failed to establish a new connection: [Errno 111] Connection refused'))

During handling of the above exception, another exception occurred:

Traceback (most recent call last):
  File "/home/airflow/.local/lib/python3.9/site-packages/mlflow/utils/rest_utils.py", line 184, in http_request
    return _get_http_response_with_retries(
  File "/home/airflow/.local/lib/python3.9/site-packages/mlflow/utils/request_utils.py", line 237, in _get_http_response_with_retries
    return session.request(method, url, allow_redirects=allow_redirects, **kwargs)
  File "/home/airflow/.local/lib/python3.9/site-packages/requests/sessions.py", line 589, in request
    resp = self.send(prep, **send_kwargs)
  File "/home/airflow/.local/lib/python3.9/site-packages/requests/sessions.py", line 703, in send
    r = adapter.send(request, **kwargs)
  File "/home/airflow/.local/lib/python3.9/site-packages/requests/adapters.py", line 700, in send
    raise ConnectionError(e, request=request)
requests.exceptions.ConnectionError: HTTPConnectionPool(host='mlflow', port=5000): Max retries exceeded with url: /api/2.0/mlflow/experiments/get-by-name?experiment_name=ALL_Classifier (Caused by NewConnectionError('<urllib3.connection.HTTPConnection object at 0x7f356c721be0>: Failed to establish a new connection: [Errno 111] Connection refused'))

During handling of the above exception, another exception occurred:

Traceback (most recent call last):
  File "/home/airflow/.local/lib/python3.9/site-packages/airflow/task/task_runner/standard_task_runner.py", line 117, in _start_by_fork
    ret = args.func(args, dag=self.dag)
  File "/home/airflow/.local/lib/python3.9/site-packages/airflow/cli/cli_config.py", line 49, in command
    return func(*args, **kwargs)
  File "/home/airflow/.local/lib/python3.9/site-packages/airflow/utils/cli.py", line 116, in wrapper
    return f(*args, **kwargs)
  File "/home/airflow/.local/lib/python3.9/site-packages/airflow/cli/commands/task_command.py", line 483, in task_run
    task_return_code = _run_task_by_selected_method(args, _dag, ti)
  File "/home/airflow/.local/lib/python3.9/site-packages/airflow/cli/commands/task_command.py", line 256, in _run_task_by_selected_method
    return _run_raw_task(args, ti)
  File "/home/airflow/.local/lib/python3.9/site-packages/airflow/cli/commands/task_command.py", line 341, in _run_raw_task
    return ti._run_raw_task(
  File "/home/airflow/.local/lib/python3.9/site-packages/airflow/utils/session.py", line 97, in wrapper
    return func(*args, session=session, **kwargs)
  File "/home/airflow/.local/lib/python3.9/site-packages/airflow/models/taskinstance.py", line 3006, in _run_raw_task
    return _run_raw_task(
  File "/home/airflow/.local/lib/python3.9/site-packages/airflow/models/taskinstance.py", line 274, in _run_raw_task
    TaskInstance._execute_task_with_callbacks(
  File "/home/airflow/.local/lib/python3.9/site-packages/airflow/models/taskinstance.py", line 3161, in _execute_task_with_callbacks
    result = self._execute_task(context, task_orig)
  File "/home/airflow/.local/lib/python3.9/site-packages/airflow/models/taskinstance.py", line 3185, in _execute_task
    return _execute_task(self, context, task_orig)
  File "/home/airflow/.local/lib/python3.9/site-packages/airflow/models/taskinstance.py", line 768, in _execute_task
    result = _execute_callable(context=context, **execute_callable_kwargs)
  File "/home/airflow/.local/lib/python3.9/site-packages/airflow/models/taskinstance.py", line 734, in _execute_callable
    return ExecutionCallableRunner(
  File "/home/airflow/.local/lib/python3.9/site-packages/airflow/utils/operator_helpers.py", line 252, in run
    return self.func(*args, **kwargs)
  File "/home/airflow/.local/lib/python3.9/site-packages/airflow/models/baseoperator.py", line 424, in wrapper
    return func(self, *args, **kwargs)
  File "/home/airflow/.local/lib/python3.9/site-packages/airflow/operators/python.py", line 238, in execute
    return_value = self.execute_callable()
  File "/home/airflow/.local/lib/python3.9/site-packages/airflow/operators/python.py", line 256, in execute_callable
    return runner.run(*self.op_args, **self.op_kwargs)
  File "/home/airflow/.local/lib/python3.9/site-packages/airflow/utils/operator_helpers.py", line 252, in run
    return self.func(*args, **kwargs)
  File "/opt/scripts/train_classifier.py", line 58, in train_classifier
    mlflow.set_experiment("ALL_Classifier")
  File "/home/airflow/.local/lib/python3.9/site-packages/mlflow/tracking/fluent.py", line 157, in set_experiment
    experiment = client.get_experiment_by_name(experiment_name)
  File "/home/airflow/.local/lib/python3.9/site-packages/mlflow/tracking/client.py", line 1703, in get_experiment_by_name
    return self._tracking_client.get_experiment_by_name(name)
  File "/home/airflow/.local/lib/python3.9/site-packages/mlflow/tracking/_tracking_service/client.py", line 591, in get_experiment_by_name
    return self.store.get_experiment_by_name(name)
  File "/home/airflow/.local/lib/python3.9/site-packages/mlflow/store/tracking/rest_store.py", line 641, in get_experiment_by_name
    response_proto = self._call_endpoint(GetExperimentByName, req_body)
  File "/home/airflow/.local/lib/python3.9/site-packages/mlflow/store/tracking/rest_store.py", line 90, in _call_endpoint
    return call_endpoint(self.get_host_creds(), endpoint, method, json_body, response_proto)
  File "/home/airflow/.local/lib/python3.9/site-packages/mlflow/utils/rest_utils.py", line 397, in call_endpoint
    response = http_request(**call_kwargs)
  File "/home/airflow/.local/lib/python3.9/site-packages/mlflow/utils/rest_utils.py", line 207, in http_request
    raise MlflowException(f"API request to {url} failed with exception {e}")
mlflow.exceptions.MlflowException: API request to http://mlflow:5000/api/2.0/mlflow/experiments/get-by-name failed with exception HTTPConnectionPool(host='mlflow', port=5000): Max retries exceeded with url: /api/2.0/mlflow/experiments/get-by-name?experiment_name=ALL_Classifier (Caused by NewConnectionError('<urllib3.connection.HTTPConnection object at 0x7f356c721be0>: Failed to establish a new connection: [Errno 111] Connection refused'))
[2025-04-30T05:29:12.457+0000] {local_task_job_runner.py:266} INFO - Task exited with return code 1
[2025-04-30T05:29:12.636+0000] {taskinstance.py:3901} INFO - 0 downstream tasks scheduled from follow-on schedule check
[2025-04-30T05:29:12.640+0000] {local_task_job_runner.py:245} INFO - ::endgroup::
